<?xml version="1.0" ?>
<sdf version="1.6">
  <world name="robot_lidar_world">
    <physics name="1ms" type="ignored">
      <max_step_size>0.001</max_step_size>
      <real_time_factor>1.0</real_time_factor>
    </physics>
    <plugin filename="gz-sim-physics-system" name="gz::sim::systems::Physics" />
    <plugin filename="gz-sim-sensors-system" name="gz::sim::systems::Sensors">
      <render_engine>ogre2</render_engine>
    </plugin>
    <plugin filename="gz-sim-scene-broadcaster-system" name="gz::sim::systems::SceneBroadcaster" />
    <plugin filename="gz-sim-user-commands-system" name="gz::sim::systems::UserCommands" />

    <light type="directional" name="sun">
      <cast_shadows>true</cast_shadows>
      <pose>0 0 10 0 0 0</pose>
      <direction>-0.5 0.1 -0.9</direction>
    </light>

    <model name="ground_plane">
      <static>true</static>
      <link name="link">
        <collision name="collision"><geometry><box><size>20 20 0.1</size></box></geometry></collision>
        <visual name="visual">
          <geometry><box><size>20 20 0.1</size></box></geometry>
          <material>
            <ambient>0.7 0.7 0.7 1</ambient>
            <diffuse>0.7 0.7 0.7 1</diffuse>
            <specular>0.1 0.1 0.1 1</specular>
          </material>
        </visual>
      </link>
    </model>

<model name="model_with_lidar">
      <pose>-4 0 0.25 0 0 0</pose>

      <link name="base_link">
        <inertial>
          <mass>20.0</mass> <inertia>
            <ixx>0.433</ixx>
            <iyy>1.083</iyy>
            <izz>1.483</izz>
          </inertia>
        </inertial>
        <visual name="visual">
          <geometry><box><size>0.8 0.5 0.1</size></box></geometry>
          <material><ambient>0 0 1 1</ambient><diffuse>0 0 1 1</diffuse></material>
        </visual>
        <collision name="collision">
          <geometry><box><size>0.8 0.5 0.1</size></box></geometry>
        </collision>

        <visual name="caster_front_visual">
          <pose>0.35 0 -0.05 0 0 0</pose>
          <geometry><sphere><radius>0.1</radius></sphere></geometry>
        </visual>
        <collision name="caster_front_collision">
          <pose>0.35 0 -0.05 0 0 0</pose>
          <geometry><sphere><radius>0.1</radius></sphere></geometry>
          <surface><friction><ode><mu>0</mu><mu2>0</mu2></ode></friction></surface>
        </collision>

        <visual name="caster_back_visual">
          <pose>-0.35 0 -0.05 0 0 0</pose>
          <geometry><sphere><radius>0.1</radius></sphere></geometry>
        </visual>
        <collision name="caster_back_collision">
          <pose>-0.35 0 -0.05 0 0 0</pose>
          <geometry><sphere><radius>0.1</radius></sphere></geometry>
          <surface><friction><ode><mu>0</mu><mu2>0</mu2></ode></friction></surface>
        </collision>
      </link>

      <link name="left_wheel">
        <pose>0 0.3 -0.05 1.5707 0 0</pose>
        <inertial>
          <mass>1.0</mass>
          <inertia><ixx>0.003</ixx><iyy>0.003</iyy><izz>0.005</izz></inertia>
        </inertial>
        <visual name="visual"><geometry><cylinder><radius>0.1</radius><length>0.05</length></cylinder></geometry></visual>
        <collision name="collision">
          <geometry><cylinder><radius>0.1</radius><length>0.05</length></cylinder></geometry>
          <surface><friction><ode><mu>1.0</mu><mu2>1.0</mu2></ode></friction></surface>
        </collision>
      </link>

      <link name="right_wheel">
        <pose>0 -0.3 -0.05 1.5707 0 0</pose>
        <inertial>
          <mass>1.0</mass>
          <inertia><ixx>0.003</ixx><iyy>0.003</iyy><izz>0.005</izz></inertia>
        </inertial>
        <visual name="visual"><geometry><cylinder><radius>0.1</radius><length>0.05</length></cylinder></geometry></visual>
        <collision name="collision">
          <geometry><cylinder><radius>0.1</radius><length>0.05</length></cylinder></geometry>
          <surface><friction><ode><mu>1.0</mu><mu2>1.0</mu2></ode></friction></surface>
        </collision>
      </link>

      <joint name="left_wheel_joint" type="revolute">
        <parent>base_link</parent>
        <child>left_wheel</child>
        <axis><xyz>0 0 -1</xyz></axis>
      </joint>
      <joint name="right_wheel_joint" type="revolute">
        <parent>base_link</parent>
        <child>right_wheel</child>
        <axis><xyz>0 0 -1</xyz></axis>
      </joint>

      <link name="lidar_link">
        <pose>0.3 0 0.1 0 0 0</pose>
        <visual name="lidar_visual">
          <geometry>
            <cylinder>
              <radius>0.03</radius>
              <length>0.1</length>
            </cylinder>
          </geometry>
          <material>
            <ambient>1 1 0 1</ambient>   <diffuse>1 1 0 1</diffuse>   <specular>0.5 0.5 0.5 1</specular>
          </material>
        </visual>        
        <sensor name='gpu_lidar' type='gpu_lidar'>
          <topic>lidar</topic>
          <update_rate>5</update_rate>
          <lidar>
            <scan><horizontal><samples>640</samples><min_angle>-3.14</min_angle><max_angle>3.14</max_angle></horizontal></scan>
            <range><min>0.08</min><max>10.0</max></range>
            <noise>
              <type>gaussian</type>
              <mean>0.0</mean>
              <stddev>0.05</stddev>
            </noise>          
          </lidar>
          <visualize>true</visualize>
        </sensor>
      </link>
      <joint name="lidar_joint" type="fixed">
        <parent>base_link</parent>
        <child>lidar_link</child>
      </joint>

      <static>false</static>

      <plugin filename="gz-sim-diff-drive-system" name="gz::sim::systems::DiffDrive">
        <left_joint>left_wheel_joint</left_joint>
        <right_joint>right_wheel_joint</right_joint>
        <wheel_separation>0.6</wheel_separation> <wheel_radius>0.1</wheel_radius>
        <topic>/model/model_with_lidar/cmd_vel</topic>
      </plugin>
    </model>

    <model name="box_1">
      <pose>0 0 0.5 0 0 0</pose>
      <link name="link">
        <inertial>
          <mass>100.0</mass> 
          <inertia>
            <ixx>16.67</ixx><iyy>16.67</iyy><izz>16.67</izz>
          </inertia>
        </inertial>      
        <collision name="c">
          <geometry><box><size>1 10 1</size></box></geometry>
          <surface>
            <friction>
              <ode>
                <mu>100.0</mu>
                <mu2>100.0</mu2>
              </ode>
            </friction>
          </surface>
        </collision>
        <visual name="v"><geometry><box><size>1 10 1</size></box></geometry><material><ambient>1 0 0 1</ambient></material></visual>
      </link>
    </model>

    <model name="box_2">
      <pose>-3 5 0.5 0 0 0.8</pose>
      <link name="link">
        <inertial>
          <mass>100.0</mass> 
          <inertia>
            <ixx>16.67</ixx><iyy>16.67</iyy><izz>16.67</izz>
          </inertia>
        </inertial>      
        <collision name="c">
          <geometry><box><size>2 2 1</size></box></geometry>
          <surface>
            <friction>
              <ode><mu>100.0</mu><mu2>100.0</mu2></ode>
            </friction>
          </surface>
        </collision>
        <visual name="v">
          <geometry><box><size>2 2 1</size></box></geometry>
          <material>
            <ambient>1 0 0 1</ambient> <diffuse>1 0 0 1</diffuse>
          </material>
        </visual>
      </link>
    </model>

    <model name="obstacle_cylinder">
      <pose>-3 -5 0.5 0 0 0</pose> <link name="link">
        <inertial>
          <mass>1.0</mass>
          <inertia>
            <ixx>0.005</ixx><iyy>0.005</iyy><izz>0.005</izz>
          </inertia>
        </inertial>
        <collision name="collision">
          <geometry>
            <cylinder>
              <radius>1.0</radius> <length>1.0</length> </cylinder>
          </geometry>
        </collision>
        <visual name="visual">
          <geometry>
            <cylinder>
              <radius>1.0</radius>
              <length>1.0</length>
            </cylinder>
          </geometry>
          <material>
            <ambient>0 1 0 1</ambient> <diffuse>0 1 0 1</diffuse>
          </material>
        </visual>
      </link>
    </model>    
  </world>
</sdf>